Workbook

Sheet Dashboard
A1: DASHBOARD • CONTROLE DE VISITAS
A2: Planejamento iniciado em 07/10/2026 • Semana 1: quarta a sexta • Semana 2: segunda e terça.
A4: Total de visitas | C4: Concluído | E4: Pendente | G4: Em andamento | I4: Reagendado | K4: Não realizado
A5: =COUNTIF(Visitas!K2:K501,"<>") | C5: =COUNTIF(Visitas!K2:K501,"Concluído") | E5: =COUNTIF(Visitas!K2:K501,"Pendente") | G5: =COUNTIF(Visitas!K2:K501,"Em andamento") | I5: =COUNTIF(Visitas!K2:K501,"Reagendado") | K5: =COUNTIF(Visitas!K2:K501,"Não realizado")
A8: Percentual de conclusão | C8: Visitas por rede | F8: Status | G8: Total | I8: Região | J8: Total
A9: =IFERROR(COUNTIF(Visitas!K2:K501,"Concluído")/COUNTIF(Visitas!K2:K501,"<>"),0) | C9: Rede | D9: Total | F9: Pendente | G9: =COUNTIF(Visitas!K2:K501,F9) | I9: Zona Norte | J9: =COUNTIF(Visitas!E2:E501,I9)
C10: Drogaria Venancio | D10: =COUNTIF(Visitas!F2:F501,"Drogaria Venancio") | F10: Em andamento | G10: =COUNTIF(Visitas!K2:K501,F10) | I10: Zona Sul | J10: =COUNTIF(Visitas!E2:E501,I10)
C11: Cristal | D11: =COUNTIF(Visitas!F2:F501,"Cristal") | F11: Concluído | G11: =COUNTIF(Visitas!K2:K501,F11) | I11: Centro / Zona Sul | J11: =COUNTIF(Visitas!E2:E501,I11)
F12: Não realizado | G12: =COUNTIF(Visitas!K2:K501,F12) | I12: Centro | J12: =COUNTIF(Visitas!E2:E501,I12)
F13: Reagendado | G13: =COUNTIF(Visitas!K2:K501,F13) | I13: Oeste | J13: =COUNTIF(Visitas!E2:E501,I13)
C14: Semana | D14: Total | I14: Mês | J14: Total
C15: Semana 1 | D15: =COUNTIF(Visitas!B2:B501,C15) | I15: janeiro | J15: =COUNTIF(Visitas!A2:A501,I15)
C16: Semana 2 | D16: =COUNTIF(Visitas!B2:B501,C16) | I16: fevereiro | J16: =COUNTIF(Visitas!A2:A501,I16)
C17: Semana 3 | D17: =COUNTIF(Visitas!B2:B501,C17) | I17: março | J17: =COUNTIF(Visitas!A2:A501,I17)
C18: Semana 4 | D18: =COUNTIF(Visitas!B2:B501,C18) | I18: abril | J18: =COUNTIF(Visitas!A2:A501,I18)
C19: Semana 5 | D19: =COUNTIF(Visitas!B2:B501,C19) | I19: maio | J19: =COUNTIF(Visitas!A2:A501,I19)
I20: junho | J20: =COUNTIF(Visitas!A2:A501,I20)
I21: julho | J21: =COUNTIF(Visitas!A2:A501,I21)
I22: agosto | J22: =COUNTIF(Visitas!A2:A501,I22)
I23: setembro | J23: =COUNTIF(Visitas!A2:A501,I23)
I24: outubro | J24: =COUNTIF(Visitas!A2:A501,I24)
I25: novembro | J25: =COUNTIF(Visitas!A2:A501,I25)
I26: dezembro | J26: =COUNTIF(Visitas!A2:A501,I26)

Sheet Rotas
A1: ROTAS DIÁRIAS • CONTROLE OPERACIONAL | L1: ROTA COMPLETA DO DIA
A2: Base de saída e retorno | B2: Rua Barão de Petrópolis, 572 — Rio Comprido, Rio de Janeiro — RJ | L2: O que o botão faz | M2: Barão de Petrópolis, 572 → todas as lojas do dia → Barão de Petrópolis, 572.
A3: Critério | B3: Ordem operacional por proximidade/região para reduzir zigue-zague. O Google Maps recalcula trânsito e percurso no momento da navegação. | L3: Transporte | M3: O link abre o Google Maps em transporte público. O Maps calcula ônibus + metrô/trem + caminhada.
A5: Dia | B5: Data | C5: Região | D5: Lojas | E5: Ordem | F5: Código | G5: Rede | H5: Unidade / Loja | I5: Endereço | J5: Navegação | L5: Dia | M5: Lojas | N5: Sequência | O5: ABRIR ROTA COMPLETA
A6: Quarta-feira | B6: 07/10/2026 | C6: Zona Sul | D6: 8 | E6: 1 | G6: Cristal | H6: G5 Drogarias Arco Verde | I6: Rua Barata Ribeiro, 147, loja B — Copacabana, Rio de Janeiro | J6: =HYPERLINK("https://www.google.com/maps/dir/?api=1&origin=Rua+Bar%C3%A3o+de+Petr%C3%B3polis%2C+572%2C+Rio+Comprido%2C+Rio+de+Janeiro%2C+RJ&destination=Rua+Barata+Ribeiro%2C+147%2C+loja+B%2C+Copacabana%2C+Rio+de+Janeiro%2C+RJ&travelmode=transit","🚌🚇 Abrir trajeto") | L6: Quarta-feira | M6: 8 | N6: Base → 8 lojas → Base | O6: =HYPERLINK("https://www.google.com/maps/dir/?api=1&origin=Rua+Bar%C3%A3o+de+Petr%C3%B3polis%2C+572%2C+Rio+Comprido%2C+Rio+de+Janeiro%2C+RJ&destination=Rua+Bar%C3%A3o+de+Petr%C3%B3polis%2C+572%2C+Rio+Comprido%2C+Rio+de+Janeiro%2C+RJ&waypoints=Rua+Barata+Ribeiro%2C+147%2C+loja+B%2C+Copacabana%2C+Rio+de+Janeiro|Rua+Barata+Ribeiro%2C+450%2C+loja+D%2C+Copacabana%2C+Rio+de+Janeiro|Av.+Nossa+Sra.+de+Copacabana%2C+872%2C+Copacabana%2C+Rio+de+Janeiro|Av.+Nossa+Sra.+de+Copacabana%2C+791-793%2C+loja+A%2C+Copacabana%2C+Rio+de+Janeiro|Rua+Siqueira+Campos%2C+107%2C+Copacabana%2C+Rio+de+Janeiro|Av.+Nossa+Sra.+de+Copacabana%2C+619%2C+Copacabana%2C+Rio+de+Janeiro|Av.+Nossa+Sra.+de+Copacabana%2C+1048%2C+loja+A%2C+Copacabana%2C+Rio+de+Janeiro|Av.+Nossa+Sra.+de+Copacabana%2C+1063%2C+loja+C%2C+Copacabana%2C+Rio+de+Janeiro&travelmode=transit","🚌🚇 ABRIR ROTA COMPLETA")
A7: Quarta-feira | B7: 07/10/2026 | C7: Zona Sul | D7: 8 | E7: 2 | G7: Cristal | H7: Drogaria Malibu | I7: Rua Barata Ribeiro, 450, loja D — Copacabana, Rio de Janeiro | J7: =HYPERLINK("https://www.google.com/maps/dir/?api=1&origin=Rua+Barata+Ribeiro%2C+147%2C+loja+B%2C+Copacabana%2C+Rio+de+Janeiro%2C+RJ&destination=Rua+Barata+Ribeiro%2C+450%2C+loja+D%2C+Copacabana%2C+Rio+de+Janeiro%2C+RJ&travelmode=transit","🚌🚇 Abrir trajeto") | L7: Quinta-feira | M7: 10 | N7: Base → 10 lojas → Base | O7: =HYPERLINK("https://www.google.com/maps/dir/?api=1&origin=Rua+Bar%C3%A3o+de+Petr%C3%B3polis%2C+572%2C+Rio+Comprido%2C+Rio+de+Janeiro%2C+RJ&destination=Rua+Bar%C3%A3o+de+Petr%C3%B3polis%2C+572%2C+Rio+Comprido%2C+Rio+de+Janeiro%2C+RJ&waypoints=Rua+Gomes+Carneiro%2C+144%2C+loja+A%2C+Ipanema%2C+Rio+de+Janeiro|Rua+Visconde+de+Piraj%C3%A1%2C+477%2C+Ipanema%2C+Rio+de+Janeiro|Rua+Visconde+de+Piraj%C3%A1%2C+174%2C+Ipanema%2C+Rio+de+Janeiro|Rua+Visconde+de+Piraj%C3%A1%2C+525%2C+loja+B%2C+Ipanema%2C+Rio+de+Janeiro|Av.+Ataulfo+de+Paiva%2C+80%2C+Leblon%2C+Rio+de+Janeiro|Rua+Jos%C3%A9+Linhares%2C+244%2C+Leblon%2C+Rio+de+Janeiro|Rua+Mario+Ribeiro%2C+231%2C+Leblon%2C+Rio+de+Janeiro|Rua+Marques+de+S%C3%A3o+Vicente%2C+39%2C+loja+A%2C+G%C3%A1vea%2C+Rio+de+Janeiro|Rua+Jardim+Bot%C3%A2nico%2C+657%2C+Jardim+Bot%C3%A2nico%2C+Rio+de+Janeiro|Rua+Jardim+Bot%C3%A2nico%2C+726%2C+Jardim+Bot%C3%A2nico%2C+Rio+de+Janeiro&travelmode=transit","🚌🚇 ABRIR ROTA COMPLETA")
A8: Quarta-feira | B8: 07/10/2026 | C8: Zona Sul | D8: 8 | E8: 3 | F8: V47 | G8: Drogaria Venancio | I8: Av. Nossa Sra. de Copacabana, 872 — Copacabana, Rio de Janeiro | J8: =HYPERLINK("https://www.google.com/maps/dir/?api=1&origin=Rua+Barata+Ribeiro%2C+450%2C+loja+D%2C+Copacabana%2C+Rio+de+Janeiro%2C+RJ&destination=Av.+Nossa+Sra.+de+Copacabana%2C+872%2C+Copacabana%2C+Rio+de+Janeiro%2C+RJ&travelmode=transit","🚌🚇 Abrir trajeto") | L8: Sexta-feira | M8: 8 | N8: Base → 8 lojas → Base | O8: =HYPERLINK("https://www.google.com/maps/dir/?api=1&origin=Rua+Bar%C3%A3o+de+Petr%C3%B3polis%2C+572%2C+Rio+Comprido%2C+Rio+de+Janeiro%2C+RJ&destination=Rua+Bar%C3%A3o+de+Petr%C3%B3polis%2C+572%2C+Rio+Comprido%2C+Rio+de+Janeiro%2C+RJ&waypoints=Av.+Rio+Branco%2C+124%2C+Centro%2C+Rio+de+Janeiro|Av.+Rio+Branco%2C+185%2C+Centro%2C+Rio+de+Janeiro|Rua+Neri+Pinheiro%2C+293%2C+Cidade+Nova%2C+Rio+de+Janeiro|Rua+das+Laranjeiras%2C+183%2C+Laranjeiras%2C+Rio+de+Janeiro|Rua+Senador+Vergueiro%2C+9%2C+Flamengo%2C+Rio+de+Janeiro|Av.+Lauro+Sodr%C3%A9%2C+445%2C+Botafogo%2C+Rio+de+Janeiro|Rua+S%C3%A3o+Clemente%2C+206%2C+Botafogo%2C+Rio+de+Janeiro|Rua+Volunt%C3%A1rios+da+P%C3%A1tria%2C+128%2C+Botafogo%2C+Rio+de+Janeiro&travelmode=transit","🚌🚇 ABRIR ROTA COMPLETA")
A9: Quarta-feira | B9: 07/10/2026 | C9: Zona Sul | D9: 8 | E9: 4 | F9: V38 | G9: Drogaria Venancio | I9: Av. Nossa Sra. de Copacabana, 791-793, loja A — Copacabana, Rio de Janeiro | J9: =HYPERLINK("https://www.google.com/maps/dir/?api=1&origin=Av.+Nossa+Sra.+de+Copacabana%2C+872%2C+Copacabana%2C+Rio+de+Janeiro%2C+RJ&destination=Av.+Nossa+Sra.+de+Copacabana%2C+791-793%2C+loja+A%2C+Copacabana%2C+Rio+de+Janeiro%2C+RJ&travelmode=transit","🚌🚇 Abrir trajeto") | L9: Segunda-feira | M9: 9 | N9: Base → 9 lojas → Base | O9: =HYPERLINK("https://www.google.com/maps/dir/?api=1&origin=Rua+Bar%C3%A3o+de+Petr%C3%B3polis%2C+572%2C+Rio+Comprido%2C+Rio+de+Janeiro%2C+RJ&destination=Rua+Bar%C3%A3o+de+Petr%C3%B3polis%2C+572%2C+Rio+Comprido%2C+Rio+de+Janeiro%2C+RJ&waypoints=Rua+Bar%C3%A3o+de+Mesquita%2C+35%2C+Tijuca%2C+Rio+de+Janeiro|Rua+Conde+de+Bonfim%2C+340%2C+Tijuca%2C+Rio+de+Janeiro|Rua+Conde+de+Bonfim%2C+372%2C+Tijuca%2C+Rio+de+Janeiro|Rua+Conde+de+Bonfim%2C+532%2C+Tijuca%2C+Rio+de+Janeiro|Av.+Maracan%C3%A3%2C+834%2C+Tijuca%2C+Rio+de+Janeiro|Rua+General+Roca%2C+836%2C+Tijuca%2C+Rio+de+Janeiro|Rua+Haddock+Lobo%2C+360%2C+Tijuca%2C+Rio+de+Janeiro|Rua+Uruguai%2C+351%2C+Tijuca%2C+Rio+de+Janeiro|Rua+S%C3%A3o+Francisco+Xavier%2C+Tijuca%2C+Rio+de+Janeiro&travelmode=transit","🚌🚇 ABRIR ROTA COMPLETA")
A10: Quarta-feira | B10: 07/10/2026 | C10: Zona Sul | D10: 8 | E10: 5 | F10: V65 | G10: Drogaria Venancio | I10: Rua Siqueira Campos, 107 — Copacabana, Rio de Janeiro | J10: =HYPERLINK("https://www.google.com/maps/dir/?api=1&origin=Av.+Nossa+Sra.+de+Copacabana%2C+791-793%2C+loja+A%2C+Copacabana%2C+Rio+de+Janeiro%2C+RJ&destination=Rua+Siqueira+Campos%2C+107%2C+Copacabana%2C+Rio+de+Janeiro%2C+RJ&travelmode=transit","🚌🚇 Abrir trajeto") | L10: Terça-feira | M10: 6 | N10: Base → 6 lojas → Base | O10: =HYPERLINK("https://www.google.com/maps/dir/?api=1&origin=Rua+Bar%C3%A3o+de+Petr%C3%B3polis%2C+572%2C+Rio+Comprido%2C+Rio+de+Janeiro%2C+RJ&destination=Rua+Bar%C3%A3o+de+Petr%C3%B3polis%2C+572%2C+Rio+Comprido%2C+Rio+de+Janeiro%2C+RJ&waypoints=Rua+Dias+da+Cruz%2C+336%2C+M%C3%A9ier%2C+Rio+de+Janeiro|Rua+Dias+da+Cruz%2C+110%2F108%2C+M%C3%A9ier%2C+Rio+de+Janeiro|Av.+Dom+H%C3%A9lder+C%C3%A2mara%2C+5.273%2C+Cachambi%2C+Rio+de+Janeiro|Rua+Dr.+Bulh%C3%B5es%2C+956%2C+Engenho+de+Dentro%2C+Rio+de+Janeiro|Pra%C3%A7a+Edmundo+Rego%2C+38%2C+Graja%C3%BA%2C+Rio+de+Janeiro|Rua+Bar%C3%A3o+de+Mesquita%2C+1002%2C+Graja%C3%BA%2C+Rio+de+Janeiro&travelmode=transit","🚌🚇 ABRIR ROTA COMPLETA")
A11: Quarta-feira | B11: 07/10/2026 | C11: Zona Sul | D11: 8 | E11: 6 | F11: V140 | G11: Drogaria Venancio | I11: Av. Nossa Sra. de Copacabana, 619 — Copacabana, Rio de Janeiro | J11: =HYPERLINK("https://www.google.com/maps/dir/?api=1&origin=Rua+Siqueira+Campos%2C+107%2C+Copacabana%2C+Rio+de+Janeiro%2C+RJ&destination=Av.+Nossa+Sra.+de+Copacabana%2C+619%2C+Copacabana%2C+Rio+de+Janeiro%2C+RJ&travelmode=transit","🚌🚇 Abrir trajeto")
A12: Quarta-feira | B12: 07/10/2026 | C12: Zona Sul | D12: 8 | E12: 7 | G12: Cristal | H12: Drogaria Copa Lemos | I12: Av. Nossa Sra. de Copacabana, 1048, loja A — Copacabana, Rio de Janeiro | J12: =HYPERLINK("https://www.google.com/maps/dir/?api=1&origin=Av.+Nossa+Sra.+de+Copacabana%2C+619%2C+Copacabana%2C+Rio+de+Janeiro%2C+RJ&destination=Av.+Nossa+Sra.+de+Copacabana%2C+1048%2C+loja+A%2C+Copacabana%2C+Rio+de+Janeiro%2C+RJ&travelmode=transit","🚌🚇 Abrir trajeto") | L12: Na aba Visitas, o link abre só o endereço. Aqui, o botão é específico para a rota completa do dia.
A13: Quarta-feira | B13: 07/10/2026 | C13: Zona Sul | D13: 8 | E13: 8 | G13: Cristal | H13: Drogaria Copa Urich | I13: Av. Nossa Sra. de Copacabana, 1063, loja C — Copacabana, Rio de Janeiro | J13: =HYPERLINK("https://www.google.com/maps/dir/?api=1&origin=Av.+Nossa+Sra.+de+Copacabana%2C+1048%2C+loja+A%2C+Copacabana%2C+Rio+de+Janeiro%2C+RJ&destination=Av.+Nossa+Sra.+de+Copacabana%2C+1063%2C+loja+C%2C+Copacabana%2C+Rio+de+Janeiro%2C+RJ&travelmode=transit","🚌🚇 Abrir trajeto")
A14: Quarta-feira | B14: 07/10/2026 | C14: Zona Sul | D14: 8 | E14: 9 | F14: RETORNO | G14: Base | H14: Rio Comprido | I14: Rua Barão de Petrópolis, 572 — Rio Comprido, Rio de Janeiro | J14: =HYPERLINK("https://www.google.com/maps/dir/?api=1&origin=Av.+Nossa+Sra.+de+Copacabana%2C+1063%2C+loja+C%2C+Copacabana%2C+Rio+de+Janeiro%2C+RJ&destination=Rua+Bar%C3%A3o+de+Petr%C3%B3polis%2C+572%2C+Rio+Comprido%2C+Rio+de+Janeiro%2C+RJ&travelmode=transit","🏠 Voltar (transporte público)")
A16: Quinta-feira | B16: 08/10/2026 | C16: Zona Sul | D16: 10 | E16: 1 | G16: Cristal | H16: Drogaria Llipe Farma | I16: Rua Gomes Carneiro, 144, loja A — Ipanema, Rio de Janeiro | J16: =HYPERLINK("https://www.google.com/maps/dir/?api=1&origin=Rua+Bar%C3%A3o+de+Petr%C3%B3polis%2C+572%2C+Rio+Comprido%2C+Rio+de+Janeiro%2C+RJ&destination=Rua+Gomes+Carneiro%2C+144%2C+loja+A%2C+Ipanema%2C+Rio+de+Janeiro%2C+RJ&travelmode=transit","🚌🚇 Abrir trajeto")
A17: Quinta-feira | B17: 08/10/2026 | C17: Zona Sul | D17: 10 | E17: 2 | F17: V21 | G17: Drogaria Venancio | I17: Rua Visconde de Pirajá, 477 — Ipanema, Rio de Janeiro | J17: =HYPERLINK("https://www.google.com/maps/dir/?api=1&origin=Rua+Gomes+Carneiro%2C+144%2C+loja+A%2C+Ipanema%2C+Rio+de+Janeiro%2C+RJ&destination=Rua+Visconde+de+Piraj%C3%A1%2C+477%2C+Ipanema%2C+Rio+de+Janeiro%2C+RJ&travelmode=transit","🚌🚇 Abrir trajeto")
A18: Quinta-feira | B18: 08/10/2026 | C18: Zona Sul | D18: 10 | E18: 3 | F18: V138 | G18: Drogaria Venancio | I18: Rua Visconde de Pirajá, 174 — Ipanema, Rio de Janeiro | J18: =HYPERLINK("https://www.google.com/maps/dir/?api=1&origin=Rua+Visconde+de+Piraj%C3%A1%2C+477%2C+Ipanema%2C+Rio+de+Janeiro%2C+RJ&destination=Rua+Visconde+de+Piraj%C3%A1%2C+174%2C+Ipanema%2C+Rio+de+Janeiro%2C+RJ&travelmode=transit","🚌🚇 Abrir trajeto")
A19: Quinta-feira | B19: 08/10/2026 | C19: Zona Sul | D19: 10 | E19: 4 | G19: Cristal | H19: G5 Drogarias Ipanema | I19: Rua Visconde de Pirajá, 525, loja B — Ipanema, Rio de Janeiro | J19: =HYPERLINK("https://www.google.com/maps/dir/?api=1&origin=Rua+Visconde+de+Piraj%C3%A1%2C+174%2C+Ipanema%2C+Rio+de+Janeiro%2C+RJ&destination=Rua+Visconde+de+Piraj%C3%A1%2C+525%2C+loja+B%2C+Ipanema%2C+Rio+de+Janeiro%2C+RJ&travelmode=transit","🚌🚇 Abrir trajeto")
A20: Quinta-feira | B20: 08/10/2026 | C20: Zona Sul | D20: 10 | E20: 5 | F20: V57 | G20: Drogaria Venancio | I20: Av. Ataulfo de Paiva, 80 — Leblon, Rio de Janeiro | J20: =HYPERLINK("https://www.google.com/maps/dir/?api=1&origin=Rua+Visconde+de+Piraj%C3%A1%2C+525%2C+loja+B%2C+Ipanema%2C+Rio+de+Janeiro%2C+RJ&destination=Av.+Ataulfo+de+Paiva%2C+80%2C+Leblon%2C+Rio+de+Janeiro%2C+RJ&travelmode=transit","🚌🚇 Abrir trajeto")
A21: Quinta-feira | B21: 08/10/2026 | C21: Zona Sul | D21: 10 | E21: 6 | F21: V141 | G21: Drogaria Venancio | I21: Rua José Linhares, 244 — Leblon, Rio de Janeiro | J21: =HYPERLINK("https://www.google.com/maps/dir/?api=1&origin=Av.+Ataulfo+de+Paiva%2C+80%2C+Leblon%2C+Rio+de+Janeiro%2C+RJ&destination=Rua+Jos%C3%A9+Linhares%2C+244%2C+Leblon%2C+Rio+de+Janeiro%2C+RJ&travelmode=transit","🚌🚇 Abrir trajeto")
A22: Quinta-feira | B22: 08/10/2026 | C22: Zona Sul | D22: 10 | E22: 7 | G22: Cristal | H22: G5 Drogarias Lagoa | I22: Rua Mario Ribeiro, 231 — Leblon, Rio de Janeiro | J22: =HYPERLINK("https://www.google.com/maps/dir/?api=1&origin=Rua+Jos%C3%A9+Linhares%2C+244%2C+Leblon%2C+Rio+de+Janeiro%2C+RJ&destination=Rua+Mario+Ribeiro%2C+231%2C+Leblon%2C+Rio+de+Janeiro%2C+RJ&travelmode=transit","🚌🚇 Abrir trajeto")
A23: Quinta-feira | B23: 08/10/2026 | C23: Zona Sul | D23: 10 | E23: 8 | G23: Cristal | H23: Farmácia Providência | I23: Rua Marques de São Vicente, 39, loja A — Gávea, Rio de Janeiro | J23: =HYPERLINK("https://www.google.com/maps/dir/?api=1&origin=Rua+Mario+Ribeiro%2C+231%2C+Leblon%2C+Rio+de+Janeiro%2C+RJ&destination=Rua+Marques+de+S%C3%A3o+Vicente%2C+39%2C+loja+A%2C+G%C3%A1vea%2C+Rio+de+Janeiro%2C+RJ&travelmode=transit","🚌🚇 Abrir trajeto")
A24: Quinta-feira | B24: 08/10/2026 | C24: Zona Sul | D24: 10 | E24: 9 | F24: V81 | G24: Drogaria Venancio | I24: Rua Jardim Botânico, 657 — Jardim Botânico, Rio de Janeiro | J24: =HYPERLINK("https://www.google.com/maps/dir/?api=1&origin=Rua+Marques+de+S%C3%A3o+Vicente%2C+39%2C+loja+A%2C+G%C3%A1vea%2C+Rio+de+Janeiro%2C+RJ&destination=Rua+Jardim+Bot%C3%A2nico%2C+657%2C+Jardim+Bot%C3%A2nico%2C+Rio+de+Janeiro%2C+RJ&travelmode=transit","🚌🚇 Abrir trajeto")
A25: Quinta-feira | B25: 08/10/2026 | C25: Zona Sul | D25: 10 | E25: 10 | F25: V63 | G25: Drogaria Venancio | I25: Rua Jardim Botânico, 726 — Jardim Botânico, Rio de Janeiro | J25: =HYPERLINK("https://www.google.com/maps/dir/?api=1&origin=Rua+Jardim+Bot%C3%A2nico%2C+657%2C+Jardim+Bot%C3%A2nico%2C+Rio+de+Janeiro%2C+RJ&destination=Rua+Jardim+Bot%C3%A2nico%2C+726%2C+Jardim+Bot%C3%A2nico%2C+Rio+de+Janeiro%2C+RJ&travelmode=transit","🚌🚇 Abrir trajeto")
A26: Quinta-feira | B26: 08/10/2026 | C26: Zona Sul | D26: 10 | E26: 11 | F26: RETORNO | G26: Base | H26: Rio Comprido | I26: Rua Barão de Petrópolis, 572 — Rio Comprido, Rio de Janeiro | J26: =HYPERLINK("https://www.google.com/maps/dir/?api=1&origin=Rua+Jardim+Bot%C3%A2nico%2C+726%2C+Jardim+Bot%C3%A2nico%2C+Rio+de+Janeiro%2C+RJ&destination=Rua+Bar%C3%A3o+de+Petr%C3%B3polis%2C+572%2C+Rio+Comprido%2C+Rio+de+Janeiro%2C+RJ&travelmode=transit","🏠 Voltar (transporte público)")
A28: Sexta-feira | B28: 09/10/2026 | C28: Centro / Zona Sul | D28: 8 | E28: 1 | F28: V59 | G28: Drogaria Venancio | I28: Av. Rio Branco, 124 — Centro, Rio de Janeiro | J28: =HYPERLINK("https://www.google.com/maps/dir/?api=1&origin=Rua+Bar%C3%A3o+de+Petr%C3%B3polis%2C+572%2C+Rio+Comprido%2C+Rio+de+Janeiro%2C+RJ&destination=Av.+Rio+Branco%2C+124%2C+Centro%2C+Rio+de+Janeiro%2C+RJ&travelmode=transit","🚌🚇 Abrir trajeto")
A29: Sexta-feira | B29: 09/10/2026 | C29: Centro / Zona Sul | D29: 8 | E29: 2 | F29: V23 | G29: Drogaria Venancio | I29: Av. Rio Branco, 185 — Centro, Rio de Janeiro | J29: =HYPERLINK("https://www.google.com/maps/dir/?api=1&origin=Av.+Rio+Branco%2C+124%2C+Centro%2C+Rio+de+Janeiro%2C+RJ&destination=Av.+Rio+Branco%2C+185%2C+Centro%2C+Rio+de+Janeiro%2C+RJ&travelmode=transit","🚌🚇 Abrir trajeto")
A30: Sexta-feira | B30: 09/10/2026 | C30: Centro / Zona Sul | D30: 8 | E30: 3 | F30: V32 | G30: Drogaria Venancio | I30: Rua Neri Pinheiro, 293 — Cidade Nova, Rio de Janeiro | J30: =HYPERLINK("https://www.google.com/maps/dir/?api=1&origin=Av.+Rio+Branco%2C+185%2C+Centro%2C+Rio+de+Janeiro%2C+RJ&destination=Rua+Neri+Pinheiro%2C+293%2C+Cidade+Nova%2C+Rio+de+Janeiro%2C+RJ&travelmode=transit","🚌🚇 Abrir trajeto")
A31: Sexta-feira | B31: 09/10/2026 | C31: Centro / Zona Sul | D31: 8 | E31: 4 | F31: V121 | G31: Drogaria Venancio | I31: Rua das Laranjeiras, 183 — Laranjeiras, Rio de Janeiro | J31: =HYPERLINK("https://www.google.com/maps/dir/?api=1&origin=Rua+Neri+Pinheiro%2C+293%2C+Cidade+Nova%2C+Rio+de+Janeiro%2C+RJ&destination=Rua+das+Laranjeiras%2C+183%2C+Laranjeiras%2C+Rio+de+Janeiro%2C+RJ&travelmode=transit","🚌🚇 Abrir trajeto")
A32: Sexta-feira | B32: 09/10/2026 | C32: Centro / Zona Sul | D32: 8 | E32: 5 | F32: V108 | G32: Drogaria Venancio | I32: Rua Senador Vergueiro, 9 — Flamengo, Rio de Janeiro | J32: =HYPERLINK("https://www.google.com/maps/dir/?api=1&origin=Rua+das+Laranjeiras%2C+183%2C+Laranjeiras%2C+Rio+de+Janeiro%2C+RJ&destination=Rua+Senador+Vergueiro%2C+9%2C+Flamengo%2C+Rio+de+Janeiro%2C+RJ&travelmode=transit","🚌🚇 Abrir trajeto")
A33: Sexta-feira | B33: 09/10/2026 | C33: Centro / Zona Sul | D33: 8 | E33: 6 | F33: V132 | G33: Drogaria Venancio | I33: Av. Lauro Sodré, 445 — Botafogo, Rio de Janeiro | J33: =HYPERLINK("https://www.google.com/maps/dir/?api=1&origin=Rua+Senador+Vergueiro%2C+9%2C+Flamengo%2C+Rio+de+Janeiro%2C+RJ&destination=Av.+Lauro+Sodr%C3%A9%2C+445%2C+Botafogo%2C+Rio+de+Janeiro%2C+RJ&travelmode=transit","🚌🚇 Abrir trajeto")
A34: Sexta-feira | B34: 09/10/2026 | C34: Centro / Zona Sul | D34: 8 | E34: 7 | F34: V131 | G34: Drogaria Venancio | I34: Rua São Clemente, 206 — Botafogo, Rio de Janeiro | J34: =HYPERLINK("https://www.google.com/maps/dir/?api=1&origin=Av.+Lauro+Sodr%C3%A9%2C+445%2C+Botafogo%2C+Rio+de+Janeiro%2C+RJ&destination=Rua+S%C3%A3o+Clemente%2C+206%2C+Botafogo%2C+Rio+de+Janeiro%2C+RJ&travelmode=transit","🚌🚇 Abrir trajeto")
A35: Sexta-feira | B35: 09/10/2026 | C35: Centro / Zona Sul | D35: 8 | E35: 8 | F35: V28 | G35: Drogaria Venancio | I35: Rua Voluntários da Pátria, 128 — Botafogo, Rio de Janeiro | J35: =HYPERLINK("https://www.google.com/maps/dir/?api=1&origin=Rua+S%C3%A3o+Clemente%2C+206%2C+Botafogo%2C+Rio+de+Janeiro%2C+RJ&destination=Rua+Volunt%C3%A1rios+da+P%C3%A1tria%2C+128%2C+Botafogo%2C+Rio+de+Janeiro%2C+RJ&travelmode=transit","🚌🚇 Abrir trajeto")
A36: Sexta-feira | B36: 09/10/2026 | C36: Centro / Zona Sul | D36: 8 | E36: 9 | F36: RETORNO | G36: Base | H36: Rio Comprido | I36: Rua Barão de Petrópolis, 572 — Rio Comprido, Rio de Janeiro | J36: =HYPERLINK("https://www.google.com/maps/dir/?api=1&origin=Rua+Volunt%C3%A1rios+da+P%C3%A1tria%2C+128%2C+Botafogo%2C+Rio+de+Janeiro%2C+RJ&destination=Rua+Bar%C3%A3o+de+Petr%C3%B3polis%2C+572%2C+Rio+Comprido%2C+Rio+de+Janeiro%2C+RJ&travelmode=transit","🏠 Voltar (transporte público)")
A38: Segunda-feira | B38: 12/10/2026 | C38: Zona Norte | D38: 9 | E38: 1 | F38: V126 | G38: Drogaria Venancio | I38: Rua Barão de Mesquita, 35 — Tijuca, Rio de Janeiro | J38: =HYPERLINK("https://www.google.com/maps/dir/?api=1&origin=Rua+Bar%C3%A3o+de+Petr%C3%B3polis%2C+572%2C+Rio+Comprido%2C+Rio+de+Janeiro%2C+RJ&destination=Rua+Bar%C3%A3o+de+Mesquita%2C+35%2C+Tijuca%2C+Rio+de+Janeiro%2C+RJ&travelmode=transit","🚌🚇 Abrir trajeto")
A39: Segunda-feira | B39: 12/10/2026 | C39: Zona Norte | D39: 9 | E39: 2 | F39: V7 | G39: Drogaria Venancio | I39: Rua Conde de Bonfim, 340 — Tijuca, Rio de Janeiro | J39: =HYPERLINK("https://www.google.com/maps/dir/?api=1&origin=Rua+Bar%C3%A3o+de+Mesquita%2C+35%2C+Tijuca%2C+Rio+de+Janeiro%2C+RJ&destination=Rua+Conde+de+Bonfim%2C+340%2C+Tijuca%2C+Rio+de+Janeiro%2C+RJ&travelmode=transit","🚌🚇 Abrir trajeto")
A40: Segunda-feira | B40: 12/10/2026 | C40: Zona Norte | D40: 9 | E40: 3 | F40: V100 | G40: Drogaria Venancio | I40: Rua Conde de Bonfim, 372 — Tijuca, Rio de Janeiro | J40: =HYPERLINK("https://www.google.com/maps/dir/?api=1&origin=Rua+Conde+de+Bonfim%2C+340%2C+Tijuca%2C+Rio+de+Janeiro%2C+RJ&destination=Rua+Conde+de+Bonfim%2C+372%2C+Tijuca%2C+Rio+de+Janeiro%2C+RJ&travelmode=transit","🚌🚇 Abrir trajeto")
A41: Segunda-feira | B41: 12/10/2026 | C41: Zona Norte | D41: 9 | E41: 4 | F41: V136 | G41: Drogaria Venancio | I41: Rua Conde de Bonfim, 532 — Tijuca, Rio de Janeiro | J41: =HYPERLINK("https://www.google.com/maps/dir/?api=1&origin=Rua+Conde+de+Bonfim%2C+372%2C+Tijuca%2C+Rio+de+Janeiro%2C+RJ&destination=Rua+Conde+de+Bonfim%2C+532%2C+Tijuca%2C+Rio+de+Janeiro%2C+RJ&travelmode=transit","🚌🚇 Abrir trajeto")
A42: Segunda-feira | B42: 12/10/2026 | C42: Zona Norte | D42: 9 | E42: 5 | F42: V72 | G42: Drogaria Venancio | I42: Av. Maracanã, 834 — Tijuca, Rio de Janeiro | J42: =HYPERLINK("https://www.google.com/maps/dir/?api=1&origin=Rua+Conde+de+Bonfim%2C+532%2C+Tijuca%2C+Rio+de+Janeiro%2C+RJ&destination=Av.+Maracan%C3%A3%2C+834%2C+Tijuca%2C+Rio+de+Janeiro%2C+RJ&travelmode=transit","🚌🚇 Abrir trajeto")
A43: Segunda-feira | B43: 12/10/2026 | C43: Zona Norte | D43: 9 | E43: 6 | F43: V9 | G43: Drogaria Venancio | I43: Rua General Roca, 836 — Tijuca, Rio de Janeiro | J43: =HYPERLINK("https://www.google.com/maps/dir/?api=1&origin=Av.+Maracan%C3%A3%2C+834%2C+Tijuca%2C+Rio+de+Janeiro%2C+RJ&destination=Rua+General+Roca%2C+836%2C+Tijuca%2C+Rio+de+Janeiro%2C+RJ&travelmode=transit","🚌🚇 Abrir trajeto")
A44: Segunda-feira | B44: 12/10/2026 | C44: Zona Norte | D44: 9 | E44: 7 | F44: V116 | G44: Drogaria Venancio | I44: Rua Haddock Lobo, 360 — Tijuca, Rio de Janeiro | J44: =HYPERLINK("https://www.google.com/maps/dir/?api=1&origin=Rua+General+Roca%2C+836%2C+Tijuca%2C+Rio+de+Janeiro%2C+RJ&destination=Rua+Haddock+Lobo%2C+360%2C+Tijuca%2C+Rio+de+Janeiro%2C+RJ&travelmode=transit","🚌🚇 Abrir trajeto")
...

Sheet Visitas
A1: Mês | B1: Semana | C1: Data | D1: Dia da semana | E1: Região | F1: Rede | G1: Código | H1: Unidade / Loja | I1: Endereço | J1: Bairro | K1: Status | L1: Observações | M1: Google Maps
A2: =IF(C2="","",TEXT(C2,"mmmm")) | B2: Semana 2 | C2: 46307 | D2: =IF(C2="","",TEXT(C2,"dddd")) | E2: Zona Norte | F2: =IF(G2<>"",IF(LEFT(UPPER(TRIM(G2)),1)="V","Drogaria Venancio",""),IF(H2<>"","Cristal","")) | G2: V9 | I2: Rua General Roca, 836 | J2: Tijuca | K2: Pendente | M2: =IF(I2="","",HYPERLINK("https://www.google.com/maps/search/?api=1&query="&SUBSTITUTE(I2&", "&J2&", Rio de Janeiro"," ","+"),"Abrir no Maps"))
A3: =IF(C3="","",TEXT(C3,"mmmm")) | B3: Semana 2 | C3: 46307 | D3: =IF(C3="","",TEXT(C3,"dddd")) | E3: Zona Norte | F3: =IF(G3<>"",IF(LEFT(UPPER(TRIM(G3)),1)="V","Drogaria Venancio",""),IF(H3<>"","Cristal","")) | G3: V72 | I3: Av. Maracanã, 834 | J3: Tijuca | K3: Pendente | M3: =IF(I3="","",HYPERLINK("https://www.google.com/maps/search/?api=1&query="&SUBSTITUTE(I3&", "&J3&", Rio de Janeiro"," ","+"),"Abrir no Maps"))
A4: =IF(C4="","",TEXT(C4,"mmmm")) | B4: Semana 2 | C4: 46307 | D4: =IF(C4="","",TEXT(C4,"dddd")) | E4: Zona Norte | F4: =IF(G4<>"",IF(LEFT(UPPER(TRIM(G4)),1)="V","Drogaria Venancio",""),IF(H4<>"","Cristal","")) | G4: V100 | I4: Rua Conde de Bonfim, 372 | J4: Tijuca | K4: Pendente | M4: =IF(I4="","",HYPERLINK("https://www.google.com/maps/search/?api=1&query="&SUBSTITUTE(I4&", "&J4&", Rio de Janeiro"," ","+"),"Abrir no Maps"))
A5: =IF(C5="","",TEXT(C5,"mmmm")) | B5: Semana 2 | C5: 46307 | D5: =IF(C5="","",TEXT(C5,"dddd")) | E5: Zona Norte | F5: =IF(G5<>"",IF(LEFT(UPPER(TRIM(G5)),1)="V","Drogaria Venancio",""),IF(H5<>"","Cristal","")) | G5: V7 | I5: Rua Conde de Bonfim, 340 | J5: Tijuca | K5: Pendente | M5: =IF(I5="","",HYPERLINK("https://www.google.com/maps/search/?api=1&query="&SUBSTITUTE(I5&", "&J5&", Rio de Janeiro"," ","+"),"Abrir no Maps"))
A6: =IF(C6="","",TEXT(C6,"mmmm")) | B6: Semana 2 | C6: 46307 | D6: =IF(C6="","",TEXT(C6,"dddd")) | E6: Zona Norte | F6: =IF(G6<>"",IF(LEFT(UPPER(TRIM(G6)),1)="V","Drogaria Venancio",""),IF(H6<>"","Cristal","")) | G6: V126 | I6: Rua Barão de Mesquita, 35 | J6: Tijuca | K6: Pendente | M6: =IF(I6="","",HYPERLINK("https://www.google.com/maps/search/?api=1&query="&SUBSTITUTE(I6&", "&J6&", Rio de Janeiro"," ","+"),"Abrir no Maps"))
A7: =IF(C7="","",TEXT(C7,"mmmm")) | B7: Semana 2 | C7: 46307 | D7: =IF(C7="","",TEXT(C7,"dddd")) | E7: Zona Norte | F7: =IF(G7<>"",IF(LEFT(UPPER(TRIM(G7)),1)="V","Drogaria Venancio",""),IF(H7<>"","Cristal","")) | G7: V127 | I7: Rua São Francisco Xavier | J7: Tijuca | K7: Pendente | M7: =IF(I7="","",HYPERLINK("https://www.google.com/maps/search/?api=1&query="&SUBSTITUTE(I7&", "&J7&", Rio de Janeiro"," ","+"),"Abrir no Maps"))
A8: =IF(C8="","",TEXT(C8,"mmmm")) | B8: Semana 2 | C8: 46307 | D8: =IF(C8="","",TEXT(C8,"dddd")) | E8: Zona Norte | F8: =IF(G8<>"",IF(LEFT(UPPER(TRIM(G8)),1)="V","Drogaria Venancio",""),IF(H8<>"","Cristal","")) | G8: V116 | I8: Rua Haddock Lobo, 360 | J8: Tijuca | K8: Pendente | M8: =IF(I8="","",HYPERLINK("https://www.google.com/maps/search/?api=1&query="&SUBSTITUTE(I8&", "&J8&", Rio de Janeiro"," ","+"),"Abrir no Maps"))
A9: =IF(C9="","",TEXT(C9,"mmmm")) | B9: Semana 2 | C9: 46307 | D9: =IF(C9="","",TEXT(C9,"dddd")) | E9: Zona Norte | F9: =IF(G9<>"",IF(LEFT(UPPER(TRIM(G9)),1)="V","Drogaria Venancio",""),IF(H9<>"","Cristal","")) | G9: V133 | I9: Rua Uruguai, 351 | J9: Tijuca | K9: Pendente | M9: =IF(I9="","",HYPERLINK("https://www.google.com/maps/search/?api=1&query="&SUBSTITUTE(I9&", "&J9&", Rio de Janeiro"," ","+"),"Abrir no Maps"))
A10: =IF(C10="","",TEXT(C10,"mmmm")) | B10: Semana 2 | C10: 46307 | D10: =IF(C10="","",TEXT(C10,"dddd")) | E10: Zona Norte | F10: =IF(G10<>"",IF(LEFT(UPPER(TRIM(G10)),1)="V","Drogaria Venancio",""),IF(H10<>"","Cristal","")) | G10: V136 | I10: Rua Conde de Bonfim, 532 | J10: Tijuca | K10: Pendente | M10: =IF(I10="","",HYPERLINK("https://www.google.com/maps/search/?api=1&query="&SUBSTITUTE(I10&", "&J10&", Rio de Janeiro"," ","+"),"Abrir no Maps"))
A11: =IF(C11="","",TEXT(C11,"mmmm")) | B11: Semana 2 | C11: 46308 | D11: =IF(C11="","",TEXT(C11,"dddd")) | E11: Zona Norte | F11: =IF(G11<>"",IF(LEFT(UPPER(TRIM(G11)),1)="V","Drogaria Venancio",""),IF(H11<>"","Cristal","")) | G11: V37 | I11: Rua Dias da Cruz, 110/108 | J11: Méier | K11: Pendente | M11: =IF(I11="","",HYPERLINK("https://www.google.com/maps/search/?api=1&query="&SUBSTITUTE(I11&", "&J11&", Rio de Janeiro"," ","+"),"Abrir no Maps"))
A12: =IF(C12="","",TEXT(C12,"mmmm")) | B12: Semana 2 | C12: 46308 | D12: =IF(C12="","",TEXT(C12,"dddd")) | E12: Zona Norte | F12: =IF(G12<>"",IF(LEFT(UPPER(TRIM(G12)),1)="V","Drogaria Venancio",""),IF(H12<>"","Cristal","")) | G12: V16 | I12: Rua Dias da Cruz, 336 | J12: Méier | K12: Pendente | M12: =IF(I12="","",HYPERLINK("https://www.google.com/maps/search/?api=1&query="&SUBSTITUTE(I12&", "&J12&", Rio de Janeiro"," ","+"),"Abrir no Maps"))
A13: =IF(C13="","",TEXT(C13,"mmmm")) | B13: Semana 2 | C13: 46308 | D13: =IF(C13="","",TEXT(C13,"dddd")) | E13: Zona Norte | F13: =IF(G13<>"",IF(LEFT(UPPER(TRIM(G13)),1)="V","Drogaria Venancio",""),IF(H13<>"","Cristal","")) | G13: V95 | I13: Av. Dom Hélder Câmara, 5.273 | J13: Cachambi | K13: Pendente | M13: =IF(I13="","",HYPERLINK("https://www.google.com/maps/search/?api=1&query="&SUBSTITUTE(I13&", "&J13&", Rio de Janeiro"," ","+"),"Abrir no Maps"))
... A20: =IF(C20="","",TEXT(C20,"mmmm")) | B20: Semana 1 | C20: 46302 | D20: =IF(C20="","",TEXT(C20,"dddd")) | E20: Zona Sul | F20: =IF(G20<>"",IF(LEFT(UPPER(TRIM(G20)),1)="V","Drogaria Venancio",""),IF(H20<>"","Cristal","")) | G20: V47 | I20: Av. Nossa Sra. de Copacabana, 872 | J20: Copacabana | K20: Pendente | M20: =IF(I20="","",HYPERLINK("https://www.google.com/maps/search/?api=1&query="&SUBSTITUTE(I20&", "&J20&", Rio de Janeiro"," ","+"),"Abrir no Maps"))
A21: =IF(C21="","",TEXT(C21,"mmmm")) | B21: Semana 1 | C21: 46302 | D21: =IF(C21="","",TEXT(C21,"dddd")) | E21: Zona Sul | F21: =IF(G21<>"",IF(LEFT(UPPER(TRIM(G21)),1)="V","Drogaria Venancio",""),IF(H21<>"","Cristal","")) | H21: Drogaria Malibu | I21: Rua Barata Ribeiro, 450, loja D | J21: Copacabana | K21: Pendente | M21: =IF(I21="","",HYPERLINK("https://www.google.com/maps/search/?api=1&query="&SUBSTITUTE(I21&", "&J21&", Rio de Janeiro"," ","+"),"Abrir no Maps"))
A22: =IF(C22="","",TEXT(C22,"mmmm")) | B22: Semana 1 | C22: 46302 | D22: =IF(C22="","",TEXT(C22,"dddd")) | E22: Zona Sul | F22: =IF(G22<>"",IF(LEFT(UPPER(TRIM(G22)),1)="V","Drogaria Venancio",""),IF(H22<>"","Cristal","")) | H22: Drogaria Copa Urich | I22: Av. Nossa Sra. de Copacabana, 1063, loja C | J22: Copacabana | K22: Pendente | M22: =IF(I22="","",HYPERLINK("https://www.google.com/maps/search/?api=1&query="&SUBSTITUTE(I22&", "&J22&", Rio de Janeiro"," ","+"),"Abrir no Maps"))
A23: =IF(C23="","",TEXT(C23,"mmmm")) | B23: Semana 1 | C23: 46302 | D23: =IF(C23="","",TEXT(C23,"dddd")) | E23: Zona Sul | F23: =IF(G23<>"",IF(LEFT(UPPER(TRIM(G23)),1)="V","Drogaria Venancio",""),IF(H23<>"","Cristal","")) | H23: Drogaria Copa Lemos | I23: Av. Nossa Sra. de Copacabana, 1048, loja A | J23: Copacabana | K23: Pendente | M23: =IF(I23="","",HYPERLINK("https://www.google.com/maps/search/?api=1&query="&SUBSTITUTE(I23&", "&J23&", Rio de Janeiro"," ","+"),"Abrir no Maps"))
A24: =IF(C24="","",TEXT(C24,"mmmm")) | B24: Semana 1 | C24: 46302 | D24: =IF(C24="","",TEXT(C24,"dddd")) | E24: Zona Sul | F24: =IF(G24<>"",IF(LEFT(UPPER(TRIM(G24)),1)="V","Drogaria Venancio",""),IF(H24<>"","Cristal","")) | H24: G5 Drogarias Arco Verde | I24: Rua Barata Ribeiro, 147, loja B | J24: Copacabana | K24: Pendente | M24: =IF(I24="","",HYPERLINK("https://www.google.com/maps/search/?api=1&query="&SUBSTITUTE(I24&", "&J24&", Rio de Janeiro"," ","+"),"Abrir no Maps"))
A25: =IF(C25="","",TEXT(C25,"mmmm")) | B25: Semana 1 | C25: 46303 | D25: =IF(C25="","",TEXT(C25,"dddd")) | E25: Zona Sul | F25: =IF(G25<>"",IF(LEFT(UPPER(TRIM(G25)),1)="V","Drogaria Venancio",""),IF(H25<>"","Cristal","")) | G25: V21 | I25: Rua Visconde de Pirajá, 477 | J25: Ipanema | K25: Pendente | M25: =IF(I25="","",HYPERLINK("https://www.google.com/maps/search/?api=1&query="&SUBSTITUTE(I25&", "&J25&", Rio de Janeiro"," ","+"),"Abrir no Maps"))
A26: =IF(C26="","",TEXT(C26,"mmmm")) | B26: Semana 1 | C26: 46303 | D26: =IF(C26="","",TEXT(C26,"dddd")) | E26: Zona Sul | F26: =IF(G26<>"",IF(LEFT(UPPER(TRIM(G26)),1)="V","Drogaria Venancio",""),IF(H26<>"","Cristal","")) | G26: V138 | I26: Rua Visconde de Pirajá, 174 | J26: Ipanema | K26: Pendente | M26: =IF(I26="","",HYPERLINK("https://www.google.com/maps/search/?api=1&query="&SUBSTITUTE(I26&", "&J26&", Rio de Janeiro"," ","+"),"Abrir no Maps"))
A27: =IF(C27="","",TEXT(C27,"mmmm")) | B27: Semana 1 | C27: 46303 | D27: =IF(C27="","",TEXT(C27,"dddd")) | E27: Zona Sul | F27: =IF(G27<>"",IF(LEFT(UPPER(TRIM(G27)),1)="V","Drogaria Venancio",""),IF(H27<>"","Cristal","")) | H27: Drogaria Llipe Farma | I27: Rua Gomes Carneiro, 144, loja A | J27: Ipanema | K27: Pendente | M27: =IF(I27="","",HYPERLINK("https://www.google.com/maps/search/?api=1&query="&SUBSTITUTE(I27&", "&J27&", Rio de Janeiro"," ","+"),"Abrir no Maps"))
A28: =IF(C28="","",TEXT(C28,"mmmm")) | B28: Semana 1 | C28: 46303 | D28: =IF(C28="","",TEXT(C28,"dddd")) | E28: Zona Sul | F28: =IF(G28<>"",IF(LEFT(UPPER(TRIM(G28)),1)="V","Drogaria Venancio",""),IF(H28<>"","Cristal","")) | H28: Farmácia Drogakar | I28: Rua Visconde de Pirajá, 12, loja B | J28: Ipanema | K28: Pendente | M28: =IF(I28="","",HYPERLINK("https://www.google.com/maps/search/?api=1&query="&SUBSTITUTE(I28&", "&J28&", Rio de Janeiro"," ","+"),"Abrir no Maps"))
A29: =IF(C29="","",TEXT(C29,"mmmm")) | B29: Semana 1 | C29: 46303 | D29: =IF(C29="","",TEXT(C29,"dddd")) | E29: Zona Sul | F29: =IF(G29<>"",IF(LEFT(UPPER(TRIM(G29)),1)="V","Drogaria Venancio",""),IF(H29<>"","Cristal","")) | H29: G5 Drogarias Ipanema | I29: Rua Visconde de Pirajá, 525, loja B | J29: Ipanema | K29: Pendente | M29: =IF(I29="","",HYPERLINK("https://www.google.com/maps/search/?api=1&query="&SUBSTITUTE(I29&", "&J29&", Rio de Janeiro"," ","+"),"Abrir no Maps"))
A30: =IF(C30="","",TEXT(C30,"mmmm")) | B30: Semana 1 | C30: 46303 | D30: =IF(C30="","",TEXT(C30,"dddd")) | E30: Zona Sul | F30: =IF(G30<>"",IF(LEFT(UPPER(TRIM(G30)),1)="V","Drogaria Venancio",""),IF(H30<>"","Cristal","")) | G30: V104 | I30: Rua Ataulfo de Paiva | J30: Leblon | K30: Pendente | M30: =IF(I30="","",HYPERLINK("https://www.google.com/maps/search/?api=1&query="&SUBSTITUTE(I30&", "&J30&", Rio de Janeiro"," ","+"),"Abrir no Maps"))
A31: =IF(C31="","",TEXT(C31,"mmmm")) | B31: Semana 1 | C31: 46303 | D31: =IF(C31="","",TEXT(C31,"dddd")) | E31: Zona Sul | F31: =IF(G31<>"",IF(LEFT(UPPER(TRIM(G31)),1)="V","Drogaria Venancio",""),IF(H31<>"","Cristal","")) | G31: V141 | I31: Rua José Linhares, 244 | J31: Leblon | K31: Pendente | M31: =IF(I31="","",HYPERLINK("https://www.google.com/maps/search/?api=1&query="&SUBSTITUTE(I31&", "&J31&", Rio de Janeiro"," ","+"),"Abrir no Maps"))
A32: =IF(C32="","",TEXT(C32,"mmmm")) | B32: Semana 1 | C32: 46303 | D32: =IF(C32="","",TEXT(C32,"dddd")) | E32: Zona Sul | F32: =IF(G32<>"",IF(LEFT(UPPER(TRIM(G32)),1)="V","Drogaria Venancio",""),IF(H32<>"","Cristal","")) | G32: V57 | I32: Av. Ataulfo de Paiva, 80 | J32: Leblon | K32: Pendente | M32: =IF(I32="","",HYPERLINK("https://www.google.com/maps/search/?api=1&query="&SUBSTITUTE(I32&", "&J32&", Rio de Janeiro"," ","+"),"Abrir no Maps"))
A33: =IF(C33="","",TEXT(C33,"mmmm")) | B33: Semana 1 | C33: 46303 | D33: =IF(C33="","",TEXT(C33,"dddd")) | E33: Zona Sul | F33: =IF(G33<>"",IF(LEFT(UPPER(TRIM(G33)),1)="V","Drogaria Venancio",""),IF(H33<>"","Cristal","")) | H33: G5 Drogarias Lagoa | I33: Rua Mario Ribeiro, 231 | J33: Leblon | K33: Pendente | M33: =IF(I33="","",HYPERLINK("https://www.google.com/maps/search/?api=1&query="&SUBSTITUTE(I33&", "&J33&", Rio de Janeiro"," ","+"),"Abrir no Maps"))
A34: =IF(C34="","",TEXT(C34,"mmmm")) | B34: Semana 1 | C34: 46303 | D34: =IF(C34="","",TEXT(C34,"dddd")) | E34: Zona Sul | F34: =IF(G34<>"",IF(LEFT(UPPER(TRIM(G34)),1)="V","Drogaria Venancio",""),IF(H34<>"","Cristal","")) | H34: Farmácia Providência | I34: Rua Marques de São Vicente, 39, loja A | J34: Gávea | K34: Pendente | M34: =IF(I34="","",HYPERLINK("https://www.google.com/maps/search/?api=1&query="&SUBSTITUTE(I34&", "&J34&", Rio de Janeiro"," ","+"),"Abrir no Maps"))
A35: =IF(C35="","",TEXT(C35,"mmmm")) | B35: Semana 1 | C35: 46303 | D35: =IF(C35="","",TEXT(C35,"dddd")) | E35: Zona Sul | F35: =IF(G35<>"",IF(LEFT(UPPER(TRIM(G35)),1)="V","Drogaria Venancio",""),IF(H35<>"","Cristal","")) | G35: V81 | I35: Rua Jardim Botânico, 657 | J35: Jardim Botânico | K35: Pendente | M35: =IF(I35="","",HYPERLINK("https://www.google.com/maps/search/?api=1&query="&SUBSTITUTE(I35&", "&J35&", Rio de Janeiro"," ","+"),"Abrir no Maps"))
A36: =IF(C36="","",TEXT(C36,"mmmm")) | B36: Semana 1 | C36: 46303 | D36: =IF(C36="","",TEXT(C36,"dddd")) | E36: Zona Sul | F36: =IF(G36<>"",IF(LEFT(UPPER(TRIM(G36)),1)="V","Drogaria Venancio",""),IF(H36<>"","Cristal","")) | G36: V63 | I36: Rua Jardim Botânico, 726 | J36: Jardim Botânico | K36: Pendente | M36: =IF(I36="","",HYPERLINK("https://www.google.com/maps/search/?api=1&query="&SUBSTITUTE(I36&", "&J36&", Rio de Janeiro"," ","+"),"Abrir no Maps"))
A37: =IF(C37="","",TEXT(C37,"mmmm")) | B37: Semana 1 | C37: 46304 | D37: =IF(C37="","",TEXT(C37,"dddd")) | E37: Centro / Zona Sul | F37: =IF(G37<>"",IF(LEFT(UPPER(TRIM(G37)),1)="V","Drogaria Venancio",""),IF(H37<>"","Cristal","")) | G37: V59 | I37: Av. Rio Branco, 124 | J37: Centro | K37: Pendente | M37: =IF(I37="","",HYPERLINK("https://www.google.com/maps/search/?api=1&query="&SUBSTITUTE(I37&", "&J37&", Rio de Janeiro"," ","+"),"Abrir no Maps"))
A38: =IF(C38="","",TEXT(C38,"mmmm")) | B38: Semana 1 | C38: 46304 | D38: =IF(C38="","",TEXT(C38,"dddd")) | E38: Centro / Zona Sul | F38: =IF(G38<>"",IF(LEFT(UPPER(TRIM(G38)),1)="V","Drogaria Venancio",""),IF(H38<>"","Cristal","")) | G38: V23 | I38: Av. Rio Branco, 185 | J38: Centro | K38: Pendente | M38: =IF(I38="","",HYPERLINK("https://www.google.com/maps/search/?api=1&query="&SUBSTITUTE(I38&", "&J38&", Rio de Janeiro"," ","+"),"Abrir no Maps"))
A39: =IF(C39="","",TEXT(C39,"mmmm")) | B39: Semana 1 | C39: 46304 | D39: =IF(C39="","",TEXT(C39,"dddd")) | E39: Centro / Zona Sul | F39: =IF(G39<>"",IF(LEFT(UPPER(TRIM(G39)),1)="V","Drogaria Venancio",""),IF(H39<>"","Cristal","")) | G39: V32 | I39: Rua Neri Pinheiro, 293 | J39: Cidade Nova | K39: Pendente | M39: =IF(I39="","",HYPERLINK("https://www.google.com/maps/search/?api=1&query="&SUBSTITUTE(I39&", "&J39&", Rio de Janeiro"," ","+"),"Abrir no Maps"))
A40: =IF(C40="","",TEXT(C40,"mmmm")) | B40: Semana 1 | C40: 46304 | D40: =IF(C40="","",TEXT(C40,"dddd")) | E40: Centro / Zona Sul | F40: =IF(G40<>"",IF(LEFT(UPPER(TRIM(G40)),1)="V","Drogaria Venancio",""),IF(H40<>"","Cristal","")) | G40: V108 | I40: Rua Senador Vergueiro, 9 | J40: Flamengo | K40: Pendente | M40: =IF(I40="","",HYPERLINK("https://www.google.com/maps/search/?api=1&query="&SUBSTITUTE(I40&", "&J40&", Rio de Janeiro"," ","+"),"Abrir no Maps"))
A41: =IF(C41="","",TEXT(C41,"mmmm")) | B41: Semana 1 | C41: 46304 | D41: =IF(C41="","",TEXT(C41,"dddd")) | E41: Centro / Zona Sul | F41: =IF(G41<>"",IF(LEFT(UPPER(TRIM(G41)),1)="V","Drogaria Venancio",""),IF(H41<>"","Cristal","")) | G41: V132 | I41: Av. Lauro Sodré, 445 | J41: Botafogo | K41: Pendente | M41: =IF(I41="","",HYPERLINK("https://www.google.com/maps/search/?api=1&query="&SUBSTITUTE(I41&", "&J41&", Rio de Janeiro"," ","+"),"Abrir no Maps"))
A42: =IF(C42="","",TEXT(C42,"mmmm")) | B42: Semana 1 | C42: 46304 | D42: =IF(C42="","",TEXT(C42,"dddd")) | E42: Centro / Zona Sul | F42: =IF(G42<>"",IF(LEFT(UPPER(TRIM(G42)),1)="V","Drogaria Venancio",""),IF(H42<>"","Cristal","")) | G42: V131 | I42: Rua São Clemente, 206 | J42: Botafogo | K42: Pendente | M42: =IF(I42="","",HYPERLINK("https://www.google.com/maps/search/?api=1&query="&SUBSTITUTE(I42&", "&J42&", Rio de Janeiro"," ","+"),"Abrir no Maps"))
A43: =IF(C43="","",TEXT(C43,"mmmm")) | B43: Semana 1 | C43: 46304 | D43: =IF(C43="","",TEXT(C43,"dddd")) | E43: Centro / Zona Sul | F43: =IF(G43<>"",IF(LEFT(UPPER(TRIM(G43)),1)="V","Drogaria Venancio",""),IF(H43<>"","Cristal","")) | G43: V28 | I43: Rua Voluntários da Pátria, 128 | J43: Botafogo | K43: Pendente | M43: =IF(I43="","",HYPERLINK("https://www.google.com/maps/search/?api=1&query="&SUBSTITUTE(I43&", "&J43&", Rio de Janeiro"," ","+"),"Abrir no Maps"))
A44: =IF(C44="","",TEXT(C44,"mmmm")) | B44: Semana 1 | C44: 46304 | D44: =IF(C44="","",TEXT(C44,"dddd")) | E44: Centro / Zona Sul | F44: =IF(G44<>"",IF(LEFT(UPPER(TRIM(G44)),1)="V","Drogaria Venancio",""),IF(H44<>"","Cristal","")) | G44: V121 | I44: Rua das Laranjeiras, 183 | J44: Laranjeiras | K44: Pendente | M44: =IF(I44="","",HYPERLINK("https://www.google.com/maps/search/?api=1&query="&SUBSTITUTE(I44&", "&J44&", Rio de Janeiro"," ","+"),"Abrir no Maps"))
A45: =IF(C45="","",TEXT(C45,"mmmm")) | B45: =IF(C45="","","Semana "&ROUNDUP(DAY(C45)/7,0)) | D45: =IF(C45="","",TEXT(C45,"dddd")) | F45: =IF(G45<>"",IF(LEFT(UPPER(TRIM(G45)),1)="V","Drogaria Venancio",""),IF(H45<>"","Cristal","")) | M45: =IF(I45="","",HYPERLINK("https://www.google.com/maps/search/?api=1&query="&SUBSTITUTE(I45&", "&J45&", Rio de Janeiro"," ","+"),"Abrir no Maps"))
A46: =IF(C46="","",TEXT(C46,"mmmm")) | B46: =IF(C46="","","Semana "&ROUNDUP(DAY(C46)/7,0)) | D46: =IF(C46="","",TEXT(C46,"dddd")) | F46: =IF(G46<>"",IF(LEFT(UPPER(TRIM(G46)),1)="V","Drogaria Venancio",""),IF(H46<>"","Cristal","")) | M46: =IF(I46="","",HYPERLINK("https://www.google.com/maps/search/?api=1&query="&SUBSTITUTE(I46&", "&J46&", Rio de Janeiro"," ","+"),"Abrir no Maps"))
...

Sheet Cadastro Rápido
A1: CADASTRO RÁPIDO
A2: Cole uma ou várias linhas em A5. Use o formato: Código/Loja — Endereço — Bairro.
A4: Texto original | B4: Data | C4: Região | D4: Código (auto) | E4: Rede (auto) | F4: Unidade / Loja (auto) | G4: Endereço (auto) | H4: Bairro (auto)
D5: =IF(A5="","",IF(LEFT(UPPER(TRIM(A5)),1)="V",IFERROR(TEXTBEFORE(TRIM(A5),"—"),TRIM(A5)),"")) | E5: =IF(A5="","",IF(LEFT(UPPER(TRIM(A5)),1)="V","Drogaria Venancio","Cristal")) | F5: =IF(A5="","",IF(LEFT(UPPER(TRIM(A5)),1)="V","",TRIM(SUBSTITUTE(IFERROR(TRIM(TEXTBEFORE(A5,"—")),TRIM(A5)),"(Cristal)","")))) | G5: =IF(A5="","",IFERROR(TRIM(TEXTBEFORE(TEXTAFTER(A5,"—"),"—")),"")) | H5: =IF(A5="","",IFERROR(TRIM(TEXTAFTER(A5,"—",2)),""))
D6: =IF(A6="","",IF(LEFT(UPPER(TRIM(A6)),1)="V",IFERROR(TEXTBEFORE(TRIM(A6),"—"),TRIM(A6)),"")) | E6: =IF(A6="","",IF(LEFT(UPPER(TRIM(A6)),1)="V","Drogaria Venancio","Cristal")) | F6: =IF(A6="","",IF(LEFT(UPPER(TRIM(A6)),1)="V","",TRIM(SUBSTITUTE(IFERROR(TRIM(TEXTBEFORE(A6,"—")),TRIM(A6)),"(Cristal)","")))) | G6: =IF(A6="","",IFERROR(TRIM(TEXTBEFORE(TEXTAFTER(A6,"—"),"—")),"")) | H6: =IF(A6="","",IFERROR(TRIM(TEXTAFTER(A6,"—",2)),""))
D7: =IF(A7="","",IF(LEFT(UPPER(TRIM(A7)),1)="V",IFERROR(TEXTBEFORE(TRIM(A7),"—"),TRIM(A7)),"")) | E7: =IF(A7="","",IF(LEFT(UPPER(TRIM(A7)),1)="V","Drogaria Venancio","Cristal")) | F7: =IF(A7="","",IF(LEFT(UPPER(TRIM(A7)),1)="V","",TRIM(SUBSTITUTE(IFERROR(TRIM(TEXTBEFORE(A7,"—")),TRIM(A7)),"(Cristal)","")))) | G7: =IF(A7="","",IFERROR(TRIM(TEXTBEFORE(TEXTAFTER(A7,"—"),"—")),"")) | H7: =IF(A7="","",IFERROR(TRIM(TEXTAFTER(A7,"—",2)),""))
D8: =IF(A8="","",IF(LEFT(UPPER(TRIM(A8)),1)="V",IFERROR(TEXTBEFORE(TRIM(A8),"—"),TRIM(A8)),"")) | E8: =IF(A8="","",IF(LEFT(UPPER(TRIM(A8)),1)="V","Drogaria Venancio","Cristal")) | F8: =IF(A8="","",IF(LEFT(UPPER(TRIM(A8)),1)="V","",TRIM(SUBSTITUTE(IFERROR(TRIM(TEXTBEFORE(A8,"—")),TRIM(A8)),"(Cristal)","")))) | G8: =IF(A8="","",IFERROR(TRIM(TEXTBEFORE(TEXTAFTER(A8,"—"),"—")),"")) | H8: =IF(A8="","",IFERROR(TRIM(TEXTAFTER(A8,"—",2)),""))
D9: =IF(A9="","",IF(LEFT(UPPER(TRIM(A9)),1)="V",IFERROR(TEXTBEFORE(TRIM(A9),"—"),TRIM(A9)),"")) | E9: =IF(A9="","",IF(LEFT(UPPER(TRIM(A9)),1)="V","Drogaria Venancio","Cristal")) | F9: =IF(A9="","",IF(LEFT(UPPER(TRIM(A9)),1)="V","",TRIM(SUBSTITUTE(IFERROR(TRIM(TEXTBEFORE(A9,"—")),TRIM(A9)),"(Cristal)","")))) | G9: =IF(A9="","",IFERROR(TRIM(TEXTBEFORE(TEXTAFTER(A9,"—"),"—")),"")) | H9: =IF(A9="","",IFERROR(TRIM(TEXTAFTER(A9,"—",2)),""))
D10: =IF(A10="","",IF(LEFT(UPPER(TRIM(A10)),1)="V",IFERROR(TEXTBEFORE(TRIM(A10),"—"),TRIM(A10)),"")) | E10: =IF(A10="","",IF(LEFT(UPPER(TRIM(A10)),1)="V","Drogaria Venancio","Cristal")) | F10: =IF(A10="","",IF(LEFT(UPPER(TRIM(A10)),1)="V","",TRIM(SUBSTITUTE(IFERROR(TRIM(TEXTBEFORE(A10,"—")),TRIM(A10)),"(Cristal)","")))) | G10: =IF(A10="","",IFERROR(TRIM(TEXTBEFORE(TEXTAFTER(A10,"—"),"—")),"")) | H10: =IF(A10="","",IFERROR(TRIM(TEXTAFTER(A10,"—",2)),""))
D11: =IF(A11="","",IF(LEFT(UPPER(TRIM(A11)),1)="V",IFERROR(TEXTBEFORE(TRIM(A11),"—"),TRIM(A11)),"")) | E11: =IF(A11="","",IF(LEFT(UPPER(TRIM(A11)),1)="V","Drogaria Venancio","Cristal")) | F11: =IF(A11="","",IF(LEFT(UPPER(TRIM(A11)),1)="V","",TRIM(SUBSTITUTE(IFERROR(TRIM(TEXTBEFORE(A11,"—")),TRIM(A11)),"(Cristal)","")))) | G11: =IF(A11="","",IFERROR(TRIM(TEXTBEFORE(TEXTAFTER(A11,"—"),"—")),"")) | H11: =IF(A11="","",IFERROR(TRIM(TEXTAFTER(A11,"—",2)),""))
D12: =IF(A12="","",IF(LEFT(UPPER(TRIM(A12)),1)="V",IFERROR(TEXTBEFORE(TRIM(A12),"—"),TRIM(A12)),"")) | E12: =IF(A12="","",IF(LEFT(UPPER(TRIM(A12)),1)="V","Drogaria Venancio","Cristal")) | F12: =IF(A12="","",IF(LEFT(UPPER(TRIM(A12)),1)="V","",TRIM(SUBSTITUTE(IFERROR(TRIM(TEXTBEFORE(A12,"—")),TRIM(A12)),"(Cristal)","")))) | G12: =IF(A12="","",IFERROR(TRIM(TEXTBEFORE(TEXTAFTER(A12,"—"),"—")),"")) | H12: =IF(A12="","",IFERROR(TRIM(TEXTAFTER(A12,"—",2)),""))
D13: =IF(A13="","",IF(LEFT(UPPER(TRIM(A13)),1)="V",IFERROR(TEXTBEFORE(TRIM(A13),"—"),TRIM(A13)),"")) | E13: =IF(A13="","",IF(LEFT(UPPER(TRIM(A13)),1)="V","Drogaria Venancio","Cristal")) | F13: =IF(A13="","",IF(LEFT(UPPER(TRIM(A13)),1)="V","",TRIM(SUBSTITUTE(IFERROR(TRIM(TEXTBEFORE(A13,"—")),TRIM(A13)),"(Cristal)","")))) | G13: =IF(A13="","",IFERROR(TRIM(TEXTBEFORE(TEXTAFTER(A13,"—"),"—")),"")) | H13: =IF(A13="","",IFERROR(TRIM(TEXTAFTER(A13,"—",2)),""))
D14: =IF(A14="","",IF(LEFT(UPPER(TRIM(A14)),1)="V",IFERROR(TEXTBEFORE(TRIM(A14),"—"),TRIM(A14)),"")) | E14: =IF(A14="","",IF(LEFT(UPPER(TRIM(A14)),1)="V","Drogaria Venancio","Cristal")) | F14: =IF(A14="","",IF(LEFT(UPPER(TRIM(A14)),1)="V","",TRIM(SUBSTITUTE(IFERROR(TRIM(TEXTBEFORE(A14,"—")),TRIM(A14)),"(Cristal)","")))) | G14: =IF(A14="","",IFERROR(TRIM(TEXTBEFORE(TEXTAFTER(A14,"—"),"—")),"")) | H14: =IF(A14="","",IFERROR(TRIM(TEXTAFTER(A14,"—",2)),""))
D15: =IF(A15="","",IF(LEFT(UPPER(TRIM(A15)),1)="V",IFERROR(TEXTBEFORE(TRIM(A15),"—"),TRIM(A15)),"")) | E15: =IF(A15="","",IF(LEFT(UPPER(TRIM(A15)),1)="V","Drogaria Venancio","Cristal")) | F15: =IF(A15="","",IF(LEFT(UPPER(TRIM(A15)),1)="V","",TRIM(SUBSTITUTE(IFERROR(TRIM(TEXTBEFORE(A15,"—")),TRIM(A15)),"(Cristal)","")))) | G15: =IF(A15="","",IFERROR(TRIM(TEXTBEFORE(TEXTAFTER(A15,"—"),"—")),"")) | H15: =IF(A15="","",IFERROR(TRIM(TEXTAFTER(A15,"—",2)),""))
D16: =IF(A16="","",IF(LEFT(UPPER(TRIM(A16)),1)="V",IFERROR(TEXTBEFORE(TRIM(A16),"—"),TRIM(A16)),"")) | E16: =IF(A16="","",IF(LEFT(UPPER(TRIM(A16)),1)="V","Drogaria Venancio","Cristal")) | F16: =IF(A16="","",IF(LEFT(UPPER(TRIM(A16)),1)="V","",TRIM(SUBSTITUTE(IFERROR(TRIM(TEXTBEFORE(A16,"—")),TRIM(A16)),"(Cristal)","")))) | G16: =IF(A16="","",IFERROR(TRIM(TEXTBEFORE(TEXTAFTER(A16,"—"),"—")),"")) | H16: =IF(A16="","",IFERROR(TRIM(TEXTAFTER(A16,"—",2)),""))
... D104: =IF(A104="","",IF(LEFT(UPPER(TRIM(A104)),1)="V",IFERROR(TEXTBEFORE(TRIM(A104),"—"),TRIM(A104)),"")) | E104: =IF(A104="","",IF(LEFT(UPPER(TRIM(A104)),1)="V","Drogaria Venancio","Cristal")) | F104: =IF(A104="","",IF(LEFT(UPPER(TRIM(A104)),1)="V","",TRIM(SUBSTITUTE(IFERROR(TRIM(TEXTBEFORE(A104,"—")),TRIM(A104)),"(Cristal)","")))) | G104: =IF(A104="","",IFERROR(TRIM(TEXTBEFORE(TEXTAFTER(A104,"—"),"—")),"")) | H104: =IF(A104="","",IFERROR(TRIM(TEXTAFTER(A104,"—",2)),""))
A107: Como usar
A108: 1. Cole várias linhas de lojas em A5:A104.
A109: 2. Se quiser, informe Data e Região nas colunas B e C.
A110: 3. As colunas D:H identificam automaticamente código, rede, unidade, endereço e bairro.
A111: 4. Depois, copie os dados estruturados para a aba Visitas (ou use a tabela principal para cadastro definitivo).
A112: 5. Linhas iniciadas por V são classificadas como Drogaria Venancio; linhas sem V são tratadas como Cristal.

Sheet Config
A1: Listas de validação
A2: Status | C2: Redes | E2: Regiões
A3: Pendente | C3: Drogaria Venancio | E3: Zona Norte
A4: Em andamento | C4: Cristal | E4: Zona Sul
A5: Concluído | E5: Centro / Zona Sul
A6: Não realizado | E6: Centro
A7: Reagendado | E7: Oeste
